Traceback (most recent call last):
  File "03_00_Preprocessing_Haematology_2016_2018_.py", line 23, in <module>
    df_haemt = pd.read_csv(file3, sep='\t', lineterminator='\n')
  File "/home/d/dlr10/anaconda3/envs/spyder-env/lib/python3.8/site-packages/pandas/io/parsers.py", line 605, in read_csv
    return _read(filepath_or_buffer, kwds)
  File "/home/d/dlr10/anaconda3/envs/spyder-env/lib/python3.8/site-packages/pandas/io/parsers.py", line 457, in _read
    parser = TextFileReader(filepath_or_buffer, **kwds)
  File "/home/d/dlr10/anaconda3/envs/spyder-env/lib/python3.8/site-packages/pandas/io/parsers.py", line 814, in __init__
    self._engine = self._make_engine(self.engine)
  File "/home/d/dlr10/anaconda3/envs/spyder-env/lib/python3.8/site-packages/pandas/io/parsers.py", line 1045, in _make_engine
    return mapping[engine](self.f, **self.options)  # type: ignore[call-arg]
  File "/home/d/dlr10/anaconda3/envs/spyder-env/lib/python3.8/site-packages/pandas/io/parsers.py", line 1862, in __init__
    self._open_handles(src, kwds)
  File "/home/d/dlr10/anaconda3/envs/spyder-env/lib/python3.8/site-packages/pandas/io/parsers.py", line 1357, in _open_handles
    self.handles = get_handle(
  File "/home/d/dlr10/anaconda3/envs/spyder-env/lib/python3.8/site-packages/pandas/io/common.py", line 639, in get_handle
    handle = open(
FileNotFoundError: [Errno 2] No such file or directory: '/rfs/CAPAI_PhD_dflr2/dflr2/Codes_Data_2/Data/20210525_haem-results.txt'
